<?xml version="1.0" encoding="utf-8"?>
<!-- This URDF was automatically created by SolidWorks to URDF Exporter! Originally created by Stephen Brawner (brawner@gmail.com) 
     Commit Version: 1.6.0-1-g15f4949  Build Version: 1.6.7594.29634
     For more information, please see http://wiki.ros.org/sw_urdf_exporter -->
<robot name="mg400">
    <link name="dummy_link" />
    <joint name="virtual_joint" type="fixed">
        <parent link="dummy_link"/>
        <child link="base_link"/>
    </joint>
    <link name="base_link">
        <inertial>
            <origin xyz="0.000600637001378877 -2.53487071139652E-07 0.0560927888040551" rpy="0 0 0"/>
            <mass value="3.62164811695094"/>
            <inertia
                    ixx="0.0126582175296405"
                    ixy="6.66832041405638E-08"
                    ixz="-3.52548281362717E-06"
                    iyy="0.0145891535260188"
                    iyz="5.1590165746046E-08"
                    izz="0.0195045116656827"/>
        </inertial>
        <visual>
            <origin xyz="0 0 0" rpy="0 0 0"/>
            <geometry>
                <mesh filename="package://mg400_description/meshes/base_link.dae"/>
            </geometry>
            <material name="">
                <color rgba="1 1 1 1"/>
            </material>
        </visual>
        <collision>
            <origin xyz="0 0 0" rpy="0 0 0"/>
            <geometry>
                <mesh filename="package://mg400_description/meshes/base_link.stl"/>
            </geometry>
        </collision>
    </link>
    <link name="j1_link">
        <inertial>
            <origin xyz="-0.00462092869681096 -6.88107981893256E-05 0.0569919358466287" rpy="0 0 0"/>
            <mass value="1.77056222753585"/>
            <inertia ixx="0.00605885293079559"
                     ixy="0.000156081820030751"
                     ixz="-0.000217856548509477"
                     iyy="0.00579381982248107"
                     iyz="6.2087689804721E-05"
                     izz="0.00741058257250928"/>
        </inertial>
        <visual>
            <origin xyz="0 0 0" rpy="0 0 0"/>
            <geometry>
                <mesh filename="package://mg400_description/meshes/j1_link.dae"/>
            </geometry>
            <material name="">
                <color rgba="1 1 1 1"/>
            </material>
        </visual>
        <collision>
            <origin xyz="0 0 0" rpy="0 0 0"/>
            <geometry>
                <mesh filename="package://mg400_description/meshes/j1_link.stl"/>
            </geometry>
        </collision>
    </link>
    <joint name="j1" type="revolute">
        <origin xyz="-0.005 0 0.123" rpy="0 0 0"/>
        <parent link="base_link"/>
        <child link="j1_link"/>
        <axis xyz="0 0 -1"/>
        <limit lower="-2.82" upper="2.82" effort="0" velocity="0"/>
    </joint>
    <link name="j2_link">
        <inertial>
            <origin xyz="0.0227944229654841 -0.0999789630956084 0.0409414582719255" rpy="0 0 0"/>
            <mass value="0.189535455844457"/>
            <inertia
                    ixx="0.000564904704787449"
                    ixy="8.45486795960616E-06"
                    ixz="-9.84897721286065E-09"
                    iyy="9.2970645253608E-05"
                    iyz="-1.36204324365658E-06"
                    izz="0.000531796355967479"/>
        </inertial>
        <visual>
            <origin xyz="0 0 0" rpy="0 0 0"/>
            <geometry>
                <mesh filename="package://mg400_description/meshes/j2_link.dae"/>
            </geometry>
            <material name="">
                <color rgba="1 1 1 1"/>
            </material>
        </visual>
        <collision>
            <origin xyz="0 0 0" rpy="0 0 0"/>
            <geometry>
                <mesh filename="package://mg400_description/meshes/j2_link.stl"/>
            </geometry>
        </collision>
    </link>
    <joint name="j2" type="revolute">
        <origin xyz="0.0435 0.040725 0.105" rpy="-1.5708 0 -3.1416"/>
        <parent link="j1_link"/>
        <child link="j2_link"/>
        <axis xyz="0 0 -1"/>
        <limit lower="-0.52" upper="1.57" effort="0" velocity="0"/>
    </joint>
    <link name="j3_link">
        <inertial>
            <origin xyz="0.101033998831055 -0.0203219799943335 0.00905110365810635" rpy="0 0 0"/>
            <mass value="0.0828783417879024"/>
            <inertia
                    ixx="2.258153038634E-05"
                    ixy="-3.46025738805897E-06"
                    ixz="3.7677050997279E-07"
                    iyy="0.000306112116552643"
                    iyz="2.12784735092028E-08"
                    izz="0.000296281360036385"/>
        </inertial>
        <visual>
            <origin xyz="0 0 0" rpy="0 0 0"/>
            <geometry>
                <mesh filename="package://mg400_description/meshes/j3_link.dae"/>
            </geometry>
            <material name="">
                <color rgba="1 1 1 1"/>
            </material>
        </visual>
        <collision>
            <origin xyz="0 0 0" rpy="0 0 0"/>
            <geometry>
                <mesh filename="package://mg400_description/meshes/j3_link.stl"/>
            </geometry>
        </collision>
    </link>
    <joint name="j3" type="revolute">
        <origin xyz="0 -0.175 0.049725" rpy="3.1416 0 3.1416"/>
        <parent link="j2_link"/>
        <child link="j3_link"/>
        <axis xyz="0 0 1"/>
        <limit lower="0" upper="1.57" effort="0" velocity="0"/>
    </joint>
    <link name="j4_link">
        <inertial>
            <origin xyz="0.0263385658036461 0.0378462041054955 3.34691901254465E-05" rpy="0 0 0"/>
            <mass value="0.159425645379101"/>
            <inertia
                    ixx="9.77075618894739E-05"
                    ixy="-8.32899807185037E-06"
                    ixz="1.42080021741658E-07"
                    iyy="5.49164689676407E-05"
                    iyz="2.90625684865252E-08"
                    izz="0.000104095192946821"/>
        </inertial>
        <visual>
            <origin xyz="0 0 0" rpy="0 0 0"/>
            <geometry>
                <mesh filename="package://mg400_description/meshes/j4_link.dae"/>
            </geometry>
            <material name="">
                <color rgba="1 1 1 1"/>
            </material>
        </visual>
        <collision>
            <origin xyz="0 0 0" rpy="0 0 0"/>
            <geometry>
                <mesh filename="package://mg400_description/meshes/j4_link.stl"/>
            </geometry>
        </collision>
    </link>
    <joint name="j4" type="revolute">
        <origin xyz="0.20393 -0.034472 0.009" rpy="0 0 -1.1941E-05"/>
        <parent link="j3_link"/>
        <child link="j4_link"/>
        <axis xyz="0 0 1"/>
        <limit lower="-3.14" upper="3.14" effort="0" velocity="0"/>
    </joint>
    <link name="j5_link">
        <inertial>
            <origin xyz="0.00027594614632892 -5.04397398116963E-05 -0.0047225962827615" rpy="0 0 0"/>
            <mass value="0.00735491831748959"/>
            <inertia
                    ixx="6.88523373329536E-07"
                    ixy="-2.49678777123486E-09"
                    ixz="1.03779080864319E-08"
                    iyy="6.75741408649246E-07"
                    iyz="-1.81976971744217E-09"
                    izz="1.12825777521716E-06"/>
        </inertial>
        <visual>
            <origin xyz="0 0 0" rpy="0 0 0"/>
            <geometry>
                <mesh filename="package://mg400_description/meshes/j5_link.dae"/>
            </geometry>
            <material name="">
                <color rgba="0.792156862745098 0.819607843137255 0.933333333333333 1"/>
            </material>
        </visual>
        <collision>
            <origin xyz="0 0 0" rpy="0 0 0"/>
            <geometry>
                <mesh filename="package://mg400_description/meshes/j5_link.stl"/>
            </geometry>
        </collision>
    </link>
    <joint name="J4" type="revolute">
        <origin xyz="0.037075 0.088472 0" rpy="-1.5708 0 0"/>
        <parent link="j4_link"/>
        <child link="j5_link"/>
        <axis xyz="0 0 -1"/>
        <limit lower="-3" upper="3" effort="0" velocity="0"/>
    </joint>
</robot>